Workbook

Sheet README
A1: BAPIL Technical Blueprint: indicative 36-month budget model
A2: Version 1.0, October 2026. Planning estimate only: not a quotation, not an approved budget and not secured funding.
A4: What this workbook is
A5: A spreadsheet version of blueprint/src/budget_model.py, which produces Tables 49, 50, 61 and 62 of the Blueprint.
A6: The formulas re-implement the Python model independently; the build checks that both give the same results.
A8: How to use it
A9: Change the blue cells on the Assumptions sheet. Every Calc_ sheet and the Summary sheet update automatically.
A10: Scenario levers are in the Low, Base, Adjusted base and High columns of the Assumptions sheet (yellow cells are the key ones).
A11: If you change an assumption, change it in budget_model.py too, so that the published tables stay in step.
A13: Colour legend
A14: Blue text: input or assumption. Black text: formula. Green text: link to another sheet. Yellow fill: key scenario lever.
A16: Units
... A30: Licence: CC BY 4.0. Generated by blueprint/src/make_budget_workbook.py.

Sheet Summary
A1: Summary (Tk crore)
A2: All values are formulas linked to the Calc_ sheets. Planning estimates, not approved funding.
A4: Base case by category (Table 50) | B4: Year 1 | C4: Year 2 | D4: Year 3 | E4: Total
A5: Core staff | B5: =Calc_Base!B28/10000000 -> 1.36575 | C5: =Calc_Base!C28/10000000 -> 3.1104 | D5: =Calc_Base!D28/10000000 -> 4.1360544 | E5: =Calc_Base!E28/10000000 -> 8.6122044
A6: Language editors and fellowships | B6: =Calc_Base!B29/10000000 -> 0.408 | C6: =Calc_Base!C29/10000000 -> 0.6696 | D6: =Calc_Base!D29/10000000 -> 0.8351424 | E6: =Calc_Base!E29/10000000 -> 1.9127424
A7: Compute and hosting | B7: =Calc_Base!B30/10000000 -> 1.3908 | C7: =Calc_Base!C30/10000000 -> 1.3624 | D7: =Calc_Base!D30/10000000 -> 0.740832 | E7: =Calc_Base!E30/10000000 -> 3.494032
A8: Data and annotation | B8: =Calc_Base!B31/10000000 -> 0.407 | C8: =Calc_Base!C31/10000000 -> 0.52488 | D8: =Calc_Base!D31/10000000 -> 0.460728 | E8: =Calc_Base!E31/10000000 -> 1.392608
A9: Training and outreach | B9: =Calc_Base!B32/10000000 -> 0.23 | C9: =Calc_Base!C32/10000000 -> 0.4428 | D9: =Calc_Base!D32/10000000 -> 0.478224 | E9: =Calc_Base!E32/10000000 -> 1.151024
A10: Governance, audit and evaluation | B10: =Calc_Base!B33/10000000 -> 0.31 | C10: =Calc_Base!C33/10000000 -> 0.3996 | D10: =Calc_Base!D33/10000000 -> 0.489888 | E10: =Calc_Base!E33/10000000 -> 1.199488
A11: Host overheads | B11: =Calc_Base!B35/10000000 -> 0.411155 | C11: =Calc_Base!C35/10000000 -> 0.650968 | D11: =Calc_Base!D35/10000000 -> 0.71408688 | E11: =Calc_Base!E35/10000000 -> 1.7762099
A12: Contingency | B12: =Calc_Base!B36/10000000 -> 0.2055775 | C12: =Calc_Base!C36/10000000 -> 0.325484 | D12: =Calc_Base!D36/10000000 -> 0.35704344 | E12: =Calc_Base!E36/10000000 -> 0.88810494
A13: Total | B13: =Calc_Base!B37/10000000 -> 4.7282825 | C13: =Calc_Base!C37/10000000 -> 7.486132 | D13: =Calc_Base!D37/10000000 -> 8.2119991 | E13: =Calc_Base!E37/10000000 -> 20.426414
A15: Scenarios (Table 62) | B15: Year 1 | C15: Year 2 | D15: Year 3 | E15: Total
A16: Low | B16: =Calc_Low!B37/10000000 -> 4.1964506 | C16: =Calc_Low!C37/10000000 -> 6.578506 | D16: =Calc_Low!D37/10000000 -> 7.1586561 | E16: =Calc_Low!E37/10000000 -> 17.933613
A17: Base | B17: =Calc_Base!B37/10000000 -> 4.7282825 | C17: =Calc_Base!C37/10000000 -> 7.486132 | D17: =Calc_Base!D37/10000000 -> 8.2119991 | E17: =Calc_Base!E37/10000000 -> 20.426414
A18: Adjusted base | B18: =Calc_Adjusted!B37/10000000 -> 5.29242 | C18: =Calc_Adjusted!C37/10000000 -> 8.095296 | D18: =Calc_Adjusted!D37/10000000 -> 8.8504186 | E18: =Calc_Adjusted!E37/10000000 -> 22.238135
A19: High | B19: =Calc_High!B37/10000000 -> 5.75568 | C19: =Calc_High!C37/10000000 -> 9.45834 | D19: =Calc_High!D37/10000000 -> 10.034642 | E19: =Calc_High!E37/10000000 -> 25.248662
A21: Check against the published Blueprint (rounded to 0.01 crore) | B21: Model | C21: Published | D21: Difference
A22: Base case, 36-month total (Table 50) | B22: =ROUND(Calc_Base!E37/10000000,2) -> 20.43 | C22: 20.43 | D22: =B22-C22 -> 0
A23: Low scenario total (Table 62) | B23: =ROUND(Calc_Low!E37/10000000,2) -> 17.93 | C23: 17.93 | D23: =B23-C23 -> 0
A24: Adjusted base case total (Table 62) | B24: =ROUND(Calc_Adjusted!E37/10000000,2) -> 22.24 | C24: 22.24 | D24: =B24-C24 -> 0
A25: High scenario total (Table 62) | B25: =ROUND(Calc_High!E37/10000000,2) -> 25.25 | C25: 25.25 | D25: =B25-C25 -> 0

Sheet Assumptions
A1: Scenario levers
A2: Parameter | B2: Low | C2: Base | D2: Adjusted base | E2: High | F2: Note
A3: Exchange rate (Tk per USD) | B3: 120 | C3: 124 | D3: 124 | E3: 135 | F3: Base: Bangladesh Bank weighted average rate, 19 October 2026 (Tk 123.65), rounded
A4: Annual escalation of taka costs (Years 2 and 3) | B4: 0.06 | C4: 0.08 | D4: 0.08 | E4: 0.1 | F4: Base: September 2026 CPI inflation 8.34% (BBS, as reported), rounded
A5: Average share of Year 1 posts filled | B5: 0.75 | C5: 0.75 | D5: 0.75 | E5: 0.75
A6: Multiplier on staff costs | B6: 0.85 | C6: 1 | D6: 1 | E6: 1.2
A7: Multiplier on equipment prices | B7: 0.8 | C7: 1 | D7: 1 | E7: 1.25
A8: Host overhead on direct costs | B8: 0.1 | C8: 0.1 | D8: 0.1 | E8: 0.1
A9: Contingency on direct costs | B9: 0.05 | C9: 0.05 | D9: 0.1 | E9: 0.1 | F9: Adjusted base and High use 10%, as recommended in Table 49
A10: Stage 1 adaptation compute, Year 2 (USD) | B10: 0 | C10: 0 | D10: 0 | E10: 20000 | F10: High case only: compute for Stage 1 adaptation if national compute is unavailable
A11: Include known omissions (1 = yes, 0 = no) | B11: 0 | C11: 0 | D11: 1 | E11: 0 | F11: Engagement events, P5 survey data, travel, open-access fees and staff computers (Section 17.2)
A14: Unit inputs (same in every scenario; Year 1 prices)
A15: Input | B15: Year 1 | C15: Year 2 | D15: Year 3 | E15: Unit | F15: Note
A16: Monthly cost per FTE: Director and principal investigator | B16: 300000 | E16: Tk per month | F16: Fully loaded
A17: Monthly cost per FTE: Policy research lead and analysts | B17: 150000 | E17: Tk per month | F17: Fully loaded
A18: Monthly cost per FTE: Machine learning and Bangla NLP engineers | B18: 200000 | E18: Tk per month | F18: Fully loaded
A19: Monthly cost per FTE: Data engineers | B19: 150000 | E19: Tk per month | F19: Fully loaded
A20: Monthly cost per FTE: Software and platform (DevSecOps) engineers | B20: 150000 | E20: Tk per month | F20: Fully loaded
A21: Monthly cost per FTE: Security engineer | B21: 180000 | E21: Tk per month | F21: Fully loaded
A22: Monthly cost per FTE: Governance, legal and ethics analysts | B22: 125000 | E22: Tk per month | F22: Fully loaded
A23: Monthly cost per FTE: User experience and accessibility designer | B23: 125000 | E23: Tk per month | F23: Fully loaded
A24: Monthly cost per FTE: Programme and partnership coordinator | B24: 90000 | E24: Tk per month | F24: Fully loaded
A25: Monthly cost per FTE: Training and outreach officers | B25: 80000 | E25: Tk per month | F25: Fully loaded
A26: FTE: Director and principal investigator | B26: 1 | C26: 1 | D26: 1 | E26: FTE | F26: Table 16
A27: FTE: Policy research lead and analysts | B27: 1 | C27: 2 | D27: 3 | E27: FTE | F27: Table 16
A28: FTE: Machine learning and Bangla NLP engineers | B28: 2 | C28: 3 | D28: 4 | E28: FTE | F28: Table 16
A29: FTE: Data engineers | B29: 1 | C29: 2 | D29: 2 | E29: FTE | F29: Table 16
A30: FTE: Software and platform (DevSecOps) engineers | B30: 1 | C30: 2 | D30: 2 | E30: FTE | F30: Table 16
A31: FTE: Security engineer | B31: 0.5 | C31: 1 | D31: 1 | E31: FTE | F31: Table 16
A32: FTE: Governance, legal and ethics analysts | B32: 1 | C32: 1 | D32: 2 | E32: FTE | F32: Table 16
A33: FTE: User experience and accessibility designer | B33: 0.5 | C33: 1 | D33: 1 | E33: FTE | F33: Table 16
A34: FTE: Programme and partnership coordinator | B34: 1 | C34: 1 | D34: 1 | E34: FTE | F34: Table 16
A35: FTE: Training and outreach officers | B35: 0 | C35: 1 | D35: 2 | E35: FTE | F35: Table 16
A36: Part-time Bangla language editors | B36: 1200000 | C36: 1400000 | D36: 1400000 | E36: Tk per year
A37: Graduate fellows | B37: 6 | C37: 10 | D37: 12 | E37: persons
A38: Fellowship stipend | B38: 40000 | E38: Tk per month
A39: Equipment (servers, GPU inference servers, storage) | B39: 92000 | C39: 82000 | D39: 24000 | E39: USD | F39: Y1: 3 servers, 2 GPU servers, 20 TB storage; Y2: staging and recovery; Y3: replacement and storage
A40: Hosting, power, bandwidth and licences | B40: 2500000 | C40: 3200000 | D40: 3800000 | E40: Tk per year
A41: Benchmark questions with gold passages | B41: 500 | C41: 800 | D41: 700 | E41: questions
A42: Cost per benchmark question | B42: 2500 | E42: Tk
...

Sheet Calc_Low
A1: Low scenario: line items (Tk)
A2: Line item | B2: Year 1 | C2: Year 2 | D2: Year 3 | E2: Total | F2: Category | G2: One-time
A3: Core staff salaries and on-costs | B3: =(Assumptions!$B$16*12*Assumptions!$B$26+Assumptions!$B$17*12*Assumptions!$B$27+Assumptions!$B$18*12*Assumptions!$B$28+Assumptions!$B$19*12*Assumptions!$B$29+Assumptions!$B$20*12*Assumptions!$B$30+Assumptions!$B$21*12*Assumptions!$B$31+Assumptions!$B$22*12*Assumptions!$B$32+Assumptions!$B$23*12*Assumptions!$B$33+Assumptions!$B$24*12*Assumptions!$B$34+Assumptions!$B$25*12*Assumptions!$B$35)*Assumptions!$B$6*(1+Assumptions!$B$4)^0*Assumptions!$B$5 -> 11608875 | C3: =(Assumptions!$B$16*12*Assumptions!$C$26+Assumptions!$B$17*12*Assumptions!$C$27+Assumptions!$B$18*12*Assumptions!$C$28+Assumptions!$B$19*12*Assumptions!$C$29+Assumptions!$B$20*12*Assumptions!$C$30+Assumptions!$B$21*12*Assumptions!$C$31+Assumptions!$B$22*12*Assumptions!$C$32+Assumptions!$B$23*12*Assumptions!$C$33+Assumptions!$B$24*12*Assumptions!$C$34+Assumptions!$B$25*12*Assumptions!$C$35)*Assumptions!$B$6*(1+Assumptions!$B$4)^1 -> 25948800 | D3: =(Assumptions!$B$16*12*Assumptions!$D$26+Assumptions!$B$17*12*Assumptions!$D$27+Assumptions!$B$18*12*Assumptions!$D$28+Assumptions!$B$19*12*Assumptions!$D$29+Assumptions!$B$20*12*Assumptions!$D$30+Assumptions!$B$21*12*Assumptions!$D$31+Assumptions!$B$22*12*Assumptions!$D$32+Assumptions!$B$23*12*Assumptions!$D$33+Assumptions!$B$24*12*Assumptions!$D$34+Assumptions!$B$25*12*Assumptions!$D$35)*Assumptions!$B$6*(1+Assumptions!$B$4)^2 -> 33866428 | E3: =SUM(B3:D3) -> 71424103 | F3: Core staff | G3: no
A4: Part-time Bangla language editors | B4: =Assumptions!$B$36*(1+Assumptions!$B$4)^0 -> 1200000 | C4: =Assumptions!$C$36*(1+Assumptions!$B$4)^1 -> 1484000 | D4: =Assumptions!$D$36*(1+Assumptions!$B$4)^2 -> 1573040 | E4: =SUM(B4:D4) -> 4257040 | F4: Language editors and fellowships | G4: no
A5: Graduate fellowships | B5: =Assumptions!$B$37*Assumptions!$B$38*12*(1+Assumptions!$B$4)^0 -> 2880000 | C5: =Assumptions!$C$37*Assumptions!$B$38*12*(1+Assumptions!$B$4)^1 -> 5088000 | D5: =Assumptions!$D$37*Assumptions!$B$38*12*(1+Assumptions!$B$4)^2 -> 6471936 | E5: =SUM(B5:D5) -> 14439936 | F5: Language editors and fellowships | G5: no
A6: Servers, GPUs and storage | B6: =Assumptions!$B$39*Assumptions!$B$7*Assumptions!$B$3 -> 8832000 | C6: =Assumptions!$C$39*Assumptions!$B$7*Assumptions!$B$3 -> 7872000 | D6: =Assumptions!$D$39*Assumptions!$B$7*Assumptions!$B$3 -> 2304000 | E6: =SUM(B6:D6) -> 19008000 | F6: Compute and hosting | G6: yes
A7: Hosting, power, bandwidth and licences | B7: =Assumptions!$B$40*(1+Assumptions!$B$4)^0 -> 2500000 | C7: =Assumptions!$C$40*(1+Assumptions!$B$4)^1 -> 3392000 | D7: =Assumptions!$D$40*(1+Assumptions!$B$4)^2 -> 4269680 | E7: =SUM(B7:D7) -> 10161680 | F7: Compute and hosting | G7: no
A8: Stage 1 adaptation compute (if no national compute) | B8: =0 -> 0 | C8: =Assumptions!$B$10*Assumptions!$B$3 -> 0 | D8: =0 -> 0 | E8: =SUM(B8:D8) -> 0 | F8: Compute and hosting | G8: yes
A9: Staff computers (known omission) | B9: =Assumptions!$B$11*Assumptions!$B$60*Assumptions!$B$61*Assumptions!$B$3 -> 0 | C9: =Assumptions!$B$11*Assumptions!$C$60*Assumptions!$B$61*Assumptions!$B$3 -> 0 | D9: =Assumptions!$B$11*Assumptions!$D$60*Assumptions!$B$61*Assumptions!$B$3 -> 0 | E9: =SUM(B9:D9) -> 0 | F9: Compute and hosting | G9: yes
A10: Benchmark questions and gold passages | B10: =Assumptions!$B$41*Assumptions!$B$42*(1+Assumptions!$B$4)^0 -> 1250000 | C10: =Assumptions!$C$41*Assumptions!$B$42*(1+Assumptions!$B$4)^1 -> 2120000 | D10: =Assumptions!$D$41*Assumptions!$B$42*(1+Assumptions!$B$4)^2 -> 1966300 | E10: =SUM(B10:D10) -> 5336300 | F10: Data and annotation | G10: yes
A11: Out-of-scope questions for abstention tests | B11: =Assumptions!$B$43*Assumptions!$B$44*(1+Assumptions!$B$4)^0 -> 120000 | C11: =Assumptions!$C$43*Assumptions!$B$44*(1+Assumptions!$B$4)^1 -> 63600 | D11: =Assumptions!$D$43*Assumptions!$B$44*(1+Assumptions!$B$4)^2 -> 0 | E11: =SUM(B11:D11) -> 183600 | F11: Data and annotation | G11: yes
A12: Citation-support judgements | B12: =Assumptions!$B$45*Assumptions!$B$46*(1+Assumptions!$B$4)^0 -> 200000 | C12: =Assumptions!$C$45*Assumptions!$B$46*(1+Assumptions!$B$4)^1 -> 424000 | D12: =Assumptions!$D$45*Assumptions!$B$46*(1+Assumptions!$B$4)^2 -> 449440 | E12: =SUM(B12:D12) -> 1073440 | F12: Data and annotation | G12: no
A13: OCR correction | B13: =Assumptions!$B$47*(1+Assumptions!$B$4)^0 -> 2000000 | C13: =Assumptions!$C$47*(1+Assumptions!$B$4)^1 -> 2120000 | D13: =Assumptions!$D$47*(1+Assumptions!$B$4)^2 -> 1685400 | E13: =SUM(B13:D13) -> 5805400 | F13: Data and annotation | G13: no
A14: Data agreements and custodian liaison | B14: =Assumptions!$B$48*(1+Assumptions!$B$4)^0 -> 500000 | C14: =Assumptions!$C$48*(1+Assumptions!$B$4)^1 -> 424000 | D14: =Assumptions!$D$48*(1+Assumptions!$B$4)^2 -> 337080 | E14: =SUM(B14:D14) -> 1261080 | F14: Data and annotation | G14: no
A15: Training of officials | B15: =Assumptions!$B$49*Assumptions!$B$50*(1+Assumptions!$B$4)^0 -> 1500000 | C15: =Assumptions!$C$49*Assumptions!$B$50*(1+Assumptions!$B$4)^1 -> 3180000 | D15: =Assumptions!$D$49*Assumptions!$B$50*(1+Assumptions!$B$4)^2 -> 3370800 | E15: =SUM(B15:D15) -> 8050800 | F15: Training and outreach | G15: no
A16: Specialist courses and bilingual materials | B16: =Assumptions!$B$51*(1+Assumptions!$B$4)^0 -> 800000 | C16: =Assumptions!$C$51*(1+Assumptions!$B$4)^1 -> 1166000 | D16: =Assumptions!$D$51*(1+Assumptions!$B$4)^2 -> 1235960 | E16: =SUM(B16:D16) -> 3201960 | F16: Training and outreach | G16: no
A17: Engagement events, P5 survey data, travel and open-access fees (known omission) | B17: =Assumptions!$B$11*Assumptions!$B$59*(1+Assumptions!$B$4)^0 -> 0 | C17: =Assumptions!$B$11*Assumptions!$B$59*(1+Assumptions!$B$4)^1 -> 0 | D17: =Assumptions!$B$11*Assumptions!$B$59*(1+Assumptions!$B$4)^2 -> 0 | E17: =SUM(B17:D17) -> 0 | F17: Training and outreach | G17: no
A18: Annual independent audit of systems | B18: =Assumptions!$B$52*(1+Assumptions!$B$4)^0 -> 300000 | C18: =Assumptions!$C$52*(1+Assumptions!$B$4)^1 -> 318000 | D18: =Assumptions!$D$52*(1+Assumptions!$B$4)^2 -> 337080 | E18: =SUM(B18:D18) -> 955080 | F18: Governance, audit and evaluation | G18: no
A19: Baseline study | B19: =Assumptions!$B$53*(1+Assumptions!$B$4)^0 -> 600000 | C19: =Assumptions!$C$53*(1+Assumptions!$B$4)^1 -> 0 | D19: =Assumptions!$D$53*(1+Assumptions!$B$4)^2 -> 0 | E19: =SUM(B19:D19) -> 600000 | F19: Governance, audit and evaluation | G19: yes
A20: ERRC and board honoraria | B20: =Assumptions!$B$54*(1+Assumptions!$B$4)^0 -> 800000 | C20: =Assumptions!$C$54*(1+Assumptions!$B$4)^1 -> 848000 | D20: =Assumptions!$D$54*(1+Assumptions!$B$4)^2 -> 898880 | E20: =SUM(B20:D20) -> 2546880 | F20: Governance, audit and evaluation | G20: no
A21: Independent final evaluation | B21: =Assumptions!$B$55*(1+Assumptions!$B$4)^0 -> 0 | C21: =Assumptions!$C$55*(1+Assumptions!$B$4)^1 -> 0 | D21: =Assumptions!$D$55*(1+Assumptions!$B$4)^2 -> 2809000 | E21: =SUM(B21:D21) -> 2809000 | F21: Governance, audit and evaluation | G21: yes
A22: Independent mid-term evaluation | B22: =Assumptions!$B$56*(1+Assumptions!$B$4)^0 -> 0 | C22: =Assumptions!$C$56*(1+Assumptions!$B$4)^1 -> 2120000 | D22: =Assumptions!$D$56*(1+Assumptions!$B$4)^2 -> 0 | E22: =SUM(B22:D22) -> 2120000 | F22: Governance, audit and evaluation | G22: yes
A23: Legal review | B23: =Assumptions!$B$57*(1+Assumptions!$B$4)^0 -> 800000 | C23: =Assumptions!$C$57*(1+Assumptions!$B$4)^1 -> 0 | D23: =Assumptions!$D$57*(1+Assumptions!$B$4)^2 -> 0 | E23: =SUM(B23:D23) -> 800000 | F23: Governance, audit and evaluation | G23: yes
A24: Penetration test and red team | B24: =Assumptions!$B$58*(1+Assumptions!$B$4)^0 -> 600000 | C24: =Assumptions!$C$58*(1+Assumptions!$B$4)^1 -> 636000 | D24: =Assumptions!$D$58*(1+Assumptions!$B$4)^2 -> 674160 | E24: =SUM(B24:D24) -> 1910160 | F24: Governance, audit and evaluation | G24: no
A26: Summary by category
A27: Row | B27: Year 1 | C27: Year 2 | D27: Year 3 | E27: Total | F27: Share of total
A28: Core staff | B28: =SUM(B3) -> 11608875 | C28: =SUM(C3) -> 25948800 | D28: =SUM(D3) -> 33866428 | E28: =SUM(E3) -> 71424103 | F28: =IF($E$37=0,0,E28/$E$37) -> 0.39826946
A29: Language editors and fellowships | B29: =SUM(B4,B5) -> 4080000 | C29: =SUM(C4,C5) -> 6572000 | D29: =SUM(D4,D5) -> 8044976 | E29: =SUM(E4,E5) -> 18696976 | F29: =IF($E$37=0,0,E29/$E$37) -> 0.10425661
A30: Compute and hosting | B30: =SUM(B6,B7,B8,B9) -> 11332000 | C30: =SUM(C6,C7,C8,C9) -> 11264000 | D30: =SUM(D6,D7,D8,D9) -> 6573680 | E30: =SUM(E6,E7,E8,E9) -> 29169680 | F30: =IF($E$37=0,0,E30/$E$37) -> 0.16265367
A31: Data and annotation | B31: =SUM(B10,B11,B12,B13,B14) -> 4070000 | C31: =SUM(C10,C11,C12,C13,C14) -> 5151600 | D31: =SUM(D10,D11,D12,D13,D14) -> 4438220 | E31: =SUM(E10,E11,E12,E13,E14) -> 13659820 | F31: =IF($E$37=0,0,E31/$E$37) -> 0.076168813
A32: Training and outreach | B32: =SUM(B15,B16,B17) -> 2300000 | C32: =SUM(C15,C16,C17) -> 4346000 | D32: =SUM(D15,D16,D17) -> 4606760 | E32: =SUM(E15,E16,E17) -> 11252760 | F32: =IF($E$37=0,0,E32/$E$37) -> 0.062746755
A33: Governance, audit and evaluation | B33: =SUM(B18,B19,B20,B21,B22,B23,B24) -> 3100000 | C33: =SUM(C18,C19,C20,C21,C22,C23,C24) -> 3922000 | D33: =SUM(D18,D19,D20,D21,D22,D23,D24) -> 4719120 | E33: =SUM(E18,E19,E20,E21,E22,E23,E24) -> 11741120 | F33: =IF($E$37=0,0,E33/$E$37) -> 0.065469909
A34: Direct costs | B34: =SUM(B28:B33) -> 36490875 | C34: =SUM(C28:C33) -> 57204400 | D34: =SUM(D28:D33) -> 62249184 | E34: =SUM(E28:E33) -> 1.5594446e+08 | F34: =IF($E$37=0,0,E34/$E$37) -> 0.86956522
A35: Host overheads | B35: =B34*Assumptions!$B$8 -> 3649087.5 | C35: =C34*Assumptions!$B$8 -> 5720440 | D35: =D34*Assumptions!$B$8 -> 6224918.4 | E35: =SUM(B35:D35) -> 15594446 | F35: =IF($E$37=0,0,E35/$E$37) -> 0.086956522
A36: Contingency | B36: =B34*Assumptions!$B$9 -> 1824543.8 | C36: =C34*Assumptions!$B$9 -> 2860220 | D36: =D34*Assumptions!$B$9 -> 3112459.2 | E36: =SUM(B36:D36) -> 7797222.9 | F36: =IF($E$37=0,0,E36/$E$37) -> 0.043478261
A37: Total | B37: =B34+B35+B36 -> 41964506 | C37: =C34+C35+C36 -> 65785060 | D37: =D34+D35+D36 -> 71586561 | E37: =E34+E35+E36 -> 1.7933613e+08 | F37: =IF($E$37=0,0,E37/$E$37) -> 1

Sheet Calc_Base
A1: Base scenario: line items (Tk)
A2: Line item | B2: Year 1 | C2: Year 2 | D2: Year 3 | E2: Total | F2: Category | G2: One-time
A3: Core staff salaries and on-costs | B3: =(Assumptions!$B$16*12*Assumptions!$B$26+Assumptions!$B$17*12*Assumptions!$B$27+Assumptions!$B$18*12*Assumptions!$B$28+Assumptions!$B$19*12*Assumptions!$B$29+Assumptions!$B$20*12*Assumptions!$B$30+Assumptions!$B$21*12*Assumptions!$B$31+Assumptions!$B$22*12*Assumptions!$B$32+Assumptions!$B$23*12*Assumptions!$B$33+Assumptions!$B$24*12*Assumptions!$B$34+Assumptions!$B$25*12*Assumptions!$B$35)*Assumptions!$C$6*(1+Assumptions!$C$4)^0*Assumptions!$C$5 -> 13657500 | C3: =(Assumptions!$B$16*12*Assumptions!$C$26+Assumptions!$B$17*12*Assumptions!$C$27+Assumptions!$B$18*12*Assumptions!$C$28+Assumptions!$B$19*12*Assumptions!$C$29+Assumptions!$B$20*12*Assumptions!$C$30+Assumptions!$B$21*12*Assumptions!$C$31+Assumptions!$B$22*12*Assumptions!$C$32+Assumptions!$B$23*12*Assumptions!$C$33+Assumptions!$B$24*12*Assumptions!$C$34+Assumptions!$B$25*12*Assumptions!$C$35)*Assumptions!$C$6*(1+Assumptions!$C$4)^1 -> 31104000 | D3: =(Assumptions!$B$16*12*Assumptions!$D$26+Assumptions!$B$17*12*Assumptions!$D$27+Assumptions!$B$18*12*Assumptions!$D$28+Assumptions!$B$19*12*Assumptions!$D$29+Assumptions!$B$20*12*Assumptions!$D$30+Assumptions!$B$21*12*Assumptions!$D$31+Assumptions!$B$22*12*Assumptions!$D$32+Assumptions!$B$23*12*Assumptions!$D$33+Assumptions!$B$24*12*Assumptions!$D$34+Assumptions!$B$25*12*Assumptions!$D$35)*Assumptions!$C$6*(1+Assumptions!$C$4)^2 -> 41360544 | E3: =SUM(B3:D3) -> 86122044 | F3: Core staff | G3: no
A4: Part-time Bangla language editors | B4: =Assumptions!$B$36*(1+Assumptions!$C$4)^0 -> 1200000 | C4: =Assumptions!$C$36*(1+Assumptions!$C$4)^1 -> 1512000 | D4: =Assumptions!$D$36*(1+Assumptions!$C$4)^2 -> 1632960 | E4: =SUM(B4:D4) -> 4344960 | F4: Language editors and fellowships | G4: no
A5: Graduate fellowships | B5: =Assumptions!$B$37*Assumptions!$B$38*12*(1+Assumptions!$C$4)^0 -> 2880000 | C5: =Assumptions!$C$37*Assumptions!$B$38*12*(1+Assumptions!$C$4)^1 -> 5184000 | D5: =Assumptions!$D$37*Assumptions!$B$38*12*(1+Assumptions!$C$4)^2 -> 6718464 | E5: =SUM(B5:D5) -> 14782464 | F5: Language editors and fellowships | G5: no
A6: Servers, GPUs and storage | B6: =Assumptions!$B$39*Assumptions!$C$7*Assumptions!$C$3 -> 11408000 | C6: =Assumptions!$C$39*Assumptions!$C$7*Assumptions!$C$3 -> 10168000 | D6: =Assumptions!$D$39*Assumptions!$C$7*Assumptions!$C$3 -> 2976000 | E6: =SUM(B6:D6) -> 24552000 | F6: Compute and hosting | G6: yes
A7: Hosting, power, bandwidth and licences | B7: =Assumptions!$B$40*(1+Assumptions!$C$4)^0 -> 2500000 | C7: =Assumptions!$C$40*(1+Assumptions!$C$4)^1 -> 3456000 | D7: =Assumptions!$D$40*(1+Assumptions!$C$4)^2 -> 4432320 | E7: =SUM(B7:D7) -> 10388320 | F7: Compute and hosting | G7: no
A8: Stage 1 adaptation compute (if no national compute) | B8: =0 -> 0 | C8: =Assumptions!$C$10*Assumptions!$C$3 -> 0 | D8: =0 -> 0 | E8: =SUM(B8:D8) -> 0 | F8: Compute and hosting | G8: yes
A9: Staff computers (known omission) | B9: =Assumptions!$C$11*Assumptions!$B$60*Assumptions!$B$61*Assumptions!$C$3 -> 0 | C9: =Assumptions!$C$11*Assumptions!$C$60*Assumptions!$B$61*Assumptions!$C$3 -> 0 | D9: =Assumptions!$C$11*Assumptions!$D$60*Assumptions!$B$61*Assumptions!$C$3 -> 0 | E9: =SUM(B9:D9) -> 0 | F9: Compute and hosting | G9: yes
A10: Benchmark questions and gold passages | B10: =Assumptions!$B$41*Assumptions!$B$42*(1+Assumptions!$C$4)^0 -> 1250000 | C10: =Assumptions!$C$41*Assumptions!$B$42*(1+Assumptions!$C$4)^1 -> 2160000 | D10: =Assumptions!$D$41*Assumptions!$B$42*(1+Assumptions!$C$4)^2 -> 2041200 | E10: =SUM(B10:D10) -> 5451200 | F10: Data and annotation | G10: yes
A11: Out-of-scope questions for abstention tests | B11: =Assumptions!$B$43*Assumptions!$B$44*(1+Assumptions!$C$4)^0 -> 120000 | C11: =Assumptions!$C$43*Assumptions!$B$44*(1+Assumptions!$C$4)^1 -> 64800 | D11: =Assumptions!$D$43*Assumptions!$B$44*(1+Assumptions!$C$4)^2 -> 0 | E11: =SUM(B11:D11) -> 184800 | F11: Data and annotation | G11: yes
A12: Citation-support judgements | B12: =Assumptions!$B$45*Assumptions!$B$46*(1+Assumptions!$C$4)^0 -> 200000 | C12: =Assumptions!$C$45*Assumptions!$B$46*(1+Assumptions!$C$4)^1 -> 432000 | D12: =Assumptions!$D$45*Assumptions!$B$46*(1+Assumptions!$C$4)^2 -> 466560 | E12: =SUM(B12:D12) -> 1098560 | F12: Data and annotation | G12: no
A13: OCR correction | B13: =Assumptions!$B$47*(1+Assumptions!$C$4)^0 -> 2000000 | C13: =Assumptions!$C$47*(1+Assumptions!$C$4)^1 -> 2160000 | D13: =Assumptions!$D$47*(1+Assumptions!$C$4)^2 -> 1749600 | E13: =SUM(B13:D13) -> 5909600 | F13: Data and annotation | G13: no
A14: Data agreements and custodian liaison | B14: =Assumptions!$B$48*(1+Assumptions!$C$4)^0 -> 500000 | C14: =Assumptions!$C$48*(1+Assumptions!$C$4)^1 -> 432000 | D14: =Assumptions!$D$48*(1+Assumptions!$C$4)^2 -> 349920 | E14: =SUM(B14:D14) -> 1281920 | F14: Data and annotation | G14: no
A15: Training of officials | B15: =Assumptions!$B$49*Assumptions!$B$50*(1+Assumptions!$C$4)^0 -> 1500000 | C15: =Assumptions!$C$49*Assumptions!$B$50*(1+Assumptions!$C$4)^1 -> 3240000 | D15: =Assumptions!$D$49*Assumptions!$B$50*(1+Assumptions!$C$4)^2 -> 3499200 | E15: =SUM(B15:D15) -> 8239200 | F15: Training and outreach | G15: no
A16: Specialist courses and bilingual materials | B16: =Assumptions!$B$51*(1+Assumptions!$C$4)^0 -> 800000 | C16: =Assumptions!$C$51*(1+Assumptions!$C$4)^1 -> 1188000 | D16: =Assumptions!$D$51*(1+Assumptions!$C$4)^2 -> 1283040 | E16: =SUM(B16:D16) -> 3271040 | F16: Training and outreach | G16: no
A17: Engagement events, P5 survey data, travel and open-access fees (known omission) | B17: =Assumptions!$C$11*Assumptions!$B$59*(1+Assumptions!$C$4)^0 -> 0 | C17: =Assumptions!$C$11*Assumptions!$B$59*(1+Assumptions!$C$4)^1 -> 0 | D17: =Assumptions!$C$11*Assumptions!$B$59*(1+Assumptions!$C$4)^2 -> 0 | E17: =SUM(B17:D17) -> 0 | F17: Training and outreach | G17: no
A18: Annual independent audit of systems | B18: =Assumptions!$B$52*(1+Assumptions!$C$4)^0 -> 300000 | C18: =Assumptions!$C$52*(1+Assumptions!$C$4)^1 -> 324000 | D18: =Assumptions!$D$52*(1+Assumptions!$C$4)^2 -> 349920 | E18: =SUM(B18:D18) -> 973920 | F18: Governance, audit and evaluation | G18: no
A19: Baseline study | B19: =Assumptions!$B$53*(1+Assumptions!$C$4)^0 -> 600000 | C19: =Assumptions!$C$53*(1+Assumptions!$C$4)^1 -> 0 | D19: =Assumptions!$D$53*(1+Assumptions!$C$4)^2 -> 0 | E19: =SUM(B19:D19) -> 600000 | F19: Governance, audit and evaluation | G19: yes
A20: ERRC and board honoraria | B20: =Assumptions!$B$54*(1+Assumptions!$C$4)^0 -> 800000 | C20: =Assumptions!$C$54*(1+Assumptions!$C$4)^1 -> 864000 | D20: =Assumptions!$D$54*(1+Assumptions!$C$4)^2 -> 933120 | E20: =SUM(B20:D20) -> 2597120 | F20: Governance, audit and evaluation | G20: no
A21: Independent final evaluation | B21: =Assumptions!$B$55*(1+Assumptions!$C$4)^0 -> 0 | C21: =Assumptions!$C$55*(1+Assumptions!$C$4)^1 -> 0 | D21: =Assumptions!$D$55*(1+Assumptions!$C$4)^2 -> 2916000 | E21: =SUM(B21:D21) -> 2916000 | F21: Governance, audit and evaluation | G21: yes
A22: Independent mid-term evaluation | B22: =Assumptions!$B$56*(1+Assumptions!$C$4)^0 -> 0 | C22: =Assumptions!$C$56*(1+Assumptions!$C$4)^1 -> 2160000 | D22: =Assumptions!$D$56*(1+Assumptions!$C$4)^2 -> 0 | E22: =SUM(B22:D22) -> 2160000 | F22: Governance, audit and evaluation | G22: yes
A23: Legal review | B23: =Assumptions!$B$57*(1+Assumptions!$C$4)^0 -> 800000 | C23: =Assumptions!$C$57*(1+Assumptions!$C$4)^1 -> 0 | D23: =Assumptions!$D$57*(1+Assumptions!$C$4)^2 -> 0 | E23: =SUM(B23:D23) -> 800000 | F23: Governance, audit and evaluation | G23: yes
A24: Penetration test and red team | B24: =Assumptions!$B$58*(1+Assumptions!$C$4)^0 -> 600000 | C24: =Assumptions!$C$58*(1+Assumptions!$C$4)^1 -> 648000 | D24: =Assumptions!$D$58*(1+Assumptions!$C$4)^2 -> 699840 | E24: =SUM(B24:D24) -> 1947840 | F24: Governance, audit and evaluation | G24: no
A26: Summary by category
A27: Row | B27: Year 1 | C27: Year 2 | D27: Year 3 | E27: Total | F27: Share of total
A28: Core staff | B28: =SUM(B3) -> 13657500 | C28: =SUM(C3) -> 31104000 | D28: =SUM(D3) -> 41360544 | E28: =SUM(E3) -> 86122044 | F28: =IF($E$37=0,0,E28/$E$37) -> 0.42162097
A29: Language editors and fellowships | B29: =SUM(B4,B5) -> 4080000 | C29: =SUM(C4,C5) -> 6696000 | D29: =SUM(D4,D5) -> 8351424 | E29: =SUM(E4,E5) -> 19127424 | F29: =IF($E$37=0,0,E29/$E$37) -> 0.093640638
A30: Compute and hosting | B30: =SUM(B6,B7,B8,B9) -> 13908000 | C30: =SUM(C6,C7,C8,C9) -> 13624000 | D30: =SUM(D6,D7,D8,D9) -> 7408320 | E30: =SUM(E6,E7,E8,E9) -> 34940320 | F30: =IF($E$37=0,0,E30/$E$37) -> 0.1710546
A31: Data and annotation | B31: =SUM(B10,B11,B12,B13,B14) -> 4070000 | C31: =SUM(C10,C11,C12,C13,C14) -> 5248800 | D31: =SUM(D10,D11,D12,D13,D14) -> 4607280 | E31: =SUM(E10,E11,E12,E13,E14) -> 13926080 | F31: =IF($E$37=0,0,E31/$E$37) -> 0.068176824
A32: Training and outreach | B32: =SUM(B15,B16,B17) -> 2300000 | C32: =SUM(C15,C16,C17) -> 4428000 | D32: =SUM(D15,D16,D17) -> 4782240 | E32: =SUM(E15,E16,E17) -> 11510240 | F32: =IF($E$37=0,0,E32/$E$37) -> 0.056349784
A33: Governance, audit and evaluation | B33: =SUM(B18,B19,B20,B21,B22,B23,B24) -> 3100000 | C33: =SUM(C18,C19,C20,C21,C22,C23,C24) -> 3996000 | D33: =SUM(D18,D19,D20,D21,D22,D23,D24) -> 4898880 | E33: =SUM(E18,E19,E20,E21,E22,E23,E24) -> 11994880 | F33: =IF($E$37=0,0,E33/$E$37) -> 0.058722398
A34: Direct costs | B34: =SUM(B28:B33) -> 41115500 | C34: =SUM(C28:C33) -> 65096800 | D34: =SUM(D28:D33) -> 71408688 | E34: =SUM(E28:E33) -> 177620988 | F34: =IF($E$37=0,0,E34/$E$37) -> 0.86956522
A35: Host overheads | B35: =B34*Assumptions!$C$8 -> 4111550 | C35: =C34*Assumptions!$C$8 -> 6509680 | D35: =D34*Assumptions!$C$8 -> 7140868.8 | E35: =SUM(B35:D35) -> 17762099 | F35: =IF($E$37=0,0,E35/$E$37) -> 0.086956522
A36: Contingency | B36: =B34*Assumptions!$C$9 -> 2055775 | C36: =C34*Assumptions!$C$9 -> 3254840 | D36: =D34*Assumptions!$C$9 -> 3570434.4 | E36: =SUM(B36:D36) -> 8881049.4 | F36: =IF($E$37=0,0,E36/$E$37) -> 0.043478261
A37: Total | B37: =B34+B35+B36 -> 47282825 | C37: =C34+C35+C36 -> 74861320 | D37: =D34+D35+D36 -> 82119991 | E37: =E34+E35+E36 -> 2.0426414e+08 | F37: =IF($E$37=0,0,E37/$E$37) -> 1

Sheet Calc_Adjusted
A1: Adjusted base scenario: line items (Tk)
A2: Line item | B2: Year 1 | C2: Year 2 | D2: Year 3 | E2: Total | F2: Category | G2: One-time
A3: Core staff salaries and on-costs | B3: =(Assumptions!$B$16*12*Assumptions!$B$26+Assumptions!$B$17*12*Assumptions!$B$27+Assumptions!$B$18*12*Assumptions!$B$28+Assumptions!$B$19*12*Assumptions!$B$29+Assumptions!$B$20*12*Assumptions!$B$30+Assumptions!$B$21*12*Assumptions!$B$31+Assumptions!$B$22*12*Assumptions!$B$32+Assumptions!$B$23*12*Assumptions!$B$33+Assumptions!$B$24*12*Assumptions!$B$34+Assumptions!$B$25*12*Assumptions!$B$35)*Assumptions!$D$6*(1+Assumptions!$D$4)^0*Assumptions!$D$5 -> 13657500 | C3: =(Assumptions!$B$16*12*Assumptions!$C$26+Assumptions!$B$17*12*Assumptions!$C$27+Assumptions!$B$18*12*Assumptions!$C$28+Assumptions!$B$19*12*Assumptions!$C$29+Assumptions!$B$20*12*Assumptions!$C$30+Assumptions!$B$21*12*Assumptions!$C$31+Assumptions!$B$22*12*Assumptions!$C$32+Assumptions!$B$23*12*Assumptions!$C$33+Assumptions!$B$24*12*Assumptions!$C$34+Assumptions!$B$25*12*Assumptions!$C$35)*Assumptions!$D$6*(1+Assumptions!$D$4)^1 -> 31104000 | D3: =(Assumptions!$B$16*12*Assumptions!$D$26+Assumptions!$B$17*12*Assumptions!$D$27+Assumptions!$B$18*12*Assumptions!$D$28+Assumptions!$B$19*12*Assumptions!$D$29+Assumptions!$B$20*12*Assumptions!$D$30+Assumptions!$B$21*12*Assumptions!$D$31+Assumptions!$B$22*12*Assumptions!$D$32+Assumptions!$B$23*12*Assumptions!$D$33+Assumptions!$B$24*12*Assumptions!$D$34+Assumptions!$B$25*12*Assumptions!$D$35)*Assumptions!$D$6*(1+Assumptions!$D$4)^2 -> 41360544 | E3: =SUM(B3:D3) -> 86122044 | F3: Core staff | G3: no
A4: Part-time Bangla language editors | B4: =Assumptions!$B$36*(1+Assumptions!$D$4)^0 -> 1200000 | C4: =Assumptions!$C$36*(1+Assumptions!$D$4)^1 -> 1512000 | D4: =Assumptions!$D$36*(1+Assumptions!$D$4)^2 -> 1632960 | E4: =SUM(B4:D4) -> 4344960 | F4: Language editors and fellowships | G4: no
A5: Graduate fellowships | B5: =Assumptions!$B$37*Assumptions!$B$38*12*(1+Assumptions!$D$4)^0 -> 2880000 | C5: =Assumptions!$C$37*Assumptions!$B$38*12*(1+Assumptions!$D$4)^1 -> 5184000 | D5: =Assumptions!$D$37*Assumptions!$B$38*12*(1+Assumptions!$D$4)^2 -> 6718464 | E5: =SUM(B5:D5) -> 14782464 | F5: Language editors and fellowships | G5: no
A6: Servers, GPUs and storage | B6: =Assumptions!$B$39*Assumptions!$D$7*Assumptions!$D$3 -> 11408000 | C6: =Assumptions!$C$39*Assumptions!$D$7*Assumptions!$D$3 -> 10168000 | D6: =Assumptions!$D$39*Assumptions!$D$7*Assumptions!$D$3 -> 2976000 | E6: =SUM(B6:D6) -> 24552000 | F6: Compute and hosting | G6: yes
A7: Hosting, power, bandwidth and licences | B7: =Assumptions!$B$40*(1+Assumptions!$D$4)^0 -> 2500000 | C7: =Assumptions!$C$40*(1+Assumptions!$D$4)^1 -> 3456000 | D7: =Assumptions!$D$40*(1+Assumptions!$D$4)^2 -> 4432320 | E7: =SUM(B7:D7) -> 10388320 | F7: Compute and hosting | G7: no
A8: Stage 1 adaptation compute (if no national compute) | B8: =0 -> 0 | C8: =Assumptions!$D$10*Assumptions!$D$3 -> 0 | D8: =0 -> 0 | E8: =SUM(B8:D8) -> 0 | F8: Compute and hosting | G8: yes
A9: Staff computers (known omission) | B9: =Assumptions!$D$11*Assumptions!$B$60*Assumptions!$B$61*Assumptions!$D$3 -> 1488000 | C9: =Assumptions!$D$11*Assumptions!$C$60*Assumptions!$B$61*Assumptions!$D$3 -> 744000 | D9: =Assumptions!$D$11*Assumptions!$D$60*Assumptions!$B$61*Assumptions!$D$3 -> 595200 | E9: =SUM(B9:D9) -> 2827200 | F9: Compute and hosting | G9: yes
A10: Benchmark questions and gold passages | B10: =Assumptions!$B$41*Assumptions!$B$42*(1+Assumptions!$D$4)^0 -> 1250000 | C10: =Assumptions!$C$41*Assumptions!$B$42*(1+Assumptions!$D$4)^1 -> 2160000 | D10: =Assumptions!$D$41*Assumptions!$B$42*(1+Assumptions!$D$4)^2 -> 2041200 | E10: =SUM(B10:D10) -> 5451200 | F10: Data and annotation | G10: yes
A11: Out-of-scope questions for abstention tests | B11: =Assumptions!$B$43*Assumptions!$B$44*(1+Assumptions!$D$4)^0 -> 120000 | C11: =Assumptions!$C$43*Assumptions!$B$44*(1+Assumptions!$D$4)^1 -> 64800 | D11: =Assumptions!$D$43*Assumptions!$B$44*(1+Assumptions!$D$4)^2 -> 0 | E11: =SUM(B11:D11) -> 184800 | F11: Data and annotation | G11: yes
A12: Citation-support judgements | B12: =Assumptions!$B$45*Assumptions!$B$46*(1+Assumptions!$D$4)^0 -> 200000 | C12: =Assumptions!$C$45*Assumptions!$B$46*(1+Assumptions!$D$4)^1 -> 432000 | D12: =Assumptions!$D$45*Assumptions!$B$46*(1+Assumptions!$D$4)^2 -> 466560 | E12: =SUM(B12:D12) -> 1098560 | F12: Data and annotation | G12: no
A13: OCR correction | B13: =Assumptions!$B$47*(1+Assumptions!$D$4)^0 -> 2000000 | C13: =Assumptions!$C$47*(1+Assumptions!$D$4)^1 -> 2160000 | D13: =Assumptions!$D$47*(1+Assumptions!$D$4)^2 -> 1749600 | E13: =SUM(B13:D13) -> 5909600 | F13: Data and annotation | G13: no
A14: Data agreements and custodian liaison | B14: =Assumptions!$B$48*(1+Assumptions!$D$4)^0 -> 500000 | C14: =Assumptions!$C$48*(1+Assumptions!$D$4)^1 -> 432000 | D14: =Assumptions!$D$48*(1+Assumptions!$D$4)^2 -> 349920 | E14: =SUM(B14:D14) -> 1281920 | F14: Data and annotation | G14: no
A15: Training of officials | B15: =Assumptions!$B$49*Assumptions!$B$50*(1+Assumptions!$D$4)^0 -> 1500000 | C15: =Assumptions!$C$49*Assumptions!$B$50*(1+Assumptions!$D$4)^1 -> 3240000 | D15: =Assumptions!$D$49*Assumptions!$B$50*(1+Assumptions!$D$4)^2 -> 3499200 | E15: =SUM(B15:D15) -> 8239200 | F15: Training and outreach | G15: no
A16: Specialist courses and bilingual materials | B16: =Assumptions!$B$51*(1+Assumptions!$D$4)^0 -> 800000 | C16: =Assumptions!$C$51*(1+Assumptions!$D$4)^1 -> 1188000 | D16: =Assumptions!$D$51*(1+Assumptions!$D$4)^2 -> 1283040 | E16: =SUM(B16:D16) -> 3271040 | F16: Training and outreach | G16: no
A17: Engagement events, P5 survey data, travel and open-access fees (known omission) | B17: =Assumptions!$D$11*Assumptions!$B$59*(1+Assumptions!$D$4)^0 -> 1500000 | C17: =Assumptions!$D$11*Assumptions!$B$59*(1+Assumptions!$D$4)^1 -> 1620000 | D17: =Assumptions!$D$11*Assumptions!$B$59*(1+Assumptions!$D$4)^2 -> 1749600 | E17: =SUM(B17:D17) -> 4869600 | F17: Training and outreach | G17: no
A18: Annual independent audit of systems | B18: =Assumptions!$B$52*(1+Assumptions!$D$4)^0 -> 300000 | C18: =Assumptions!$C$52*(1+Assumptions!$D$4)^1 -> 324000 | D18: =Assumptions!$D$52*(1+Assumptions!$D$4)^2 -> 349920 | E18: =SUM(B18:D18) -> 973920 | F18: Governance, audit and evaluation | G18: no
A19: Baseline study | B19: =Assumptions!$B$53*(1+Assumptions!$D$4)^0 -> 600000 | C19: =Assumptions!$C$53*(1+Assumptions!$D$4)^1 -> 0 | D19: =Assumptions!$D$53*(1+Assumptions!$D$4)^2 -> 0 | E19: =SUM(B19:D19) -> 600000 | F19: Governance, audit and evaluation | G19: yes
A20: ERRC and board honoraria | B20: =Assumptions!$B$54*(1+Assumptions!$D$4)^0 -> 800000 | C20: =Assumptions!$C$54*(1+Assumptions!$D$4)^1 -> 864000 | D20: =Assumptions!$D$54*(1+Assumptions!$D$4)^2 -> 933120 | E20: =SUM(B20:D20) -> 2597120 | F20: Governance, audit and evaluation | G20: no
A21: Independent final evaluation | B21: =Assumptions!$B$55*(1+Assumptions!$D$4)^0 -> 0 | C21: =Assumptions!$C$55*(1+Assumptions!$D$4)^1 -> 0 | D21: =Assumptions!$D$55*(1+Assumptions!$D$4)^2 -> 2916000 | E21: =SUM(B21:D21) -> 2916000 | F21: Governance, audit and evaluation | G21: yes
A22: Independent mid-term evaluation | B22: =Assumptions!$B$56*(1+Assumptions!$D$4)^0 -> 0 | C22: =Assumptions!$C$56*(1+Assumptions!$D$4)^1 -> 2160000 | D22: =Assumptions!$D$56*(1+Assumptions!$D$4)^2 -> 0 | E22: =SUM(B22:D22) -> 2160000 | F22: Governance, audit and evaluation | G22: yes
A23: Legal review | B23: =Assumptions!$B$57*(1+Assumptions!$D$4)^0 -> 800000 | C23: =Assumptions!$C$57*(1+Assumptions!$D$4)^1 -> 0 | D23: =Assumptions!$D$57*(1+Assumptions!$D$4)^2 -> 0 | E23: =SUM(B23:D23) -> 800000 | F23: Governance, audit and evaluation | G23: yes
A24: Penetration test and red team | B24: =Assumptions!$B$58*(1+Assumptions!$D$4)^0 -> 600000 | C24: =Assumptions!$C$58*(1+Assumptions!$D$4)^1 -> 648000 | D24: =Assumptions!$D$58*(1+Assumptions!$D$4)^2 -> 699840 | E24: =SUM(B24:D24) -> 1947840 | F24: Governance, audit and evaluation | G24: no
A26: Summary by category
A27: Row | B27: Year 1 | C27: Year 2 | D27: Year 3 | E27: Total | F27: Share of total
A28: Core staff | B28: =SUM(B3) -> 13657500 | C28: =SUM(C3) -> 31104000 | D28: =SUM(D3) -> 41360544 | E28: =SUM(E3) -> 86122044 | F28: =IF($E$37=0,0,E28/$E$37) -> 0.38727189
A29: Language editors and fellowships | B29: =SUM(B4,B5) -> 4080000 | C29: =SUM(C4,C5) -> 6696000 | D29: =SUM(D4,D5) -> 8351424 | E29: =SUM(E4,E5) -> 19127424 | F29: =IF($E$37=0,0,E29/$E$37) -> 0.086011819
A30: Compute and hosting | B30: =SUM(B6,B7,B8,B9) -> 15396000 | C30: =SUM(C6,C7,C8,C9) -> 14368000 | D30: =SUM(D6,D7,D8,D9) -> 8003520 | E30: =SUM(E6,E7,E8,E9) -> 37767520 | F30: =IF($E$37=0,0,E30/$E$37) -> 0.16983223
A31: Data and annotation | B31: =SUM(B10,B11,B12,B13,B14) -> 4070000 | C31: =SUM(C10,C11,C12,C13,C14) -> 5248800 | D31: =SUM(D10,D11,D12,D13,D14) -> 4607280 | E31: =SUM(E10,E11,E12,E13,E14) -> 13926080 | F31: =IF($E$37=0,0,E31/$E$37) -> 0.062622519
A32: Training and outreach | B32: =SUM(B15,B16,B17) -> 3800000 | C32: =SUM(C15,C16,C17) -> 6048000 | D32: =SUM(D15,D16,D17) -> 6531840 | E32: =SUM(E15,E16,E17) -> 16379840 | F32: =IF($E$37=0,0,E32/$E$37) -> 0.073656538
A33: Governance, audit and evaluation | B33: =SUM(B18,B19,B20,B21,B22,B23,B24) -> 3100000 | C33: =SUM(C18,C19,C20,C21,C22,C23,C24) -> 3996000 | D33: =SUM(D18,D19,D20,D21,D22,D23,D24) -> 4898880 | E33: =SUM(E18,E19,E20,E21,E22,E23,E24) -> 11994880 | F33: =IF($E$37=0,0,E33/$E$37) -> 0.053938337
A34: Direct costs | B34: =SUM(B28:B33) -> 44103500 | C34: =SUM(C28:C33) -> 67460800 | D34: =SUM(D28:D33) -> 73753488 | E34: =SUM(E28:E33) -> 185317788 | F34: =IF($E$37=0,0,E34/$E$37) -> 0.83333333
A35: Host overheads | B35: =B34*Assumptions!$D$8 -> 4410350 | C35: =C34*Assumptions!$D$8 -> 6746080 | D35: =D34*Assumptions!$D$8 -> 7375348.8 | E35: =SUM(B35:D35) -> 18531779 | F35: =IF($E$37=0,0,E35/$E$37) -> 0.083333333
A36: Contingency | B36: =B34*Assumptions!$D$9 -> 4410350 | C36: =C34*Assumptions!$D$9 -> 6746080 | D36: =D34*Assumptions!$D$9 -> 7375348.8 | E36: =SUM(B36:D36) -> 18531779 | F36: =IF($E$37=0,0,E36/$E$37) -> 0.083333333
A37: Total | B37: =B34+B35+B36 -> 52924200 | C37: =C34+C35+C36 -> 80952960 | D37: =D34+D35+D36 -> 88504186 | E37: =E34+E35+E36 -> 2.2238135e+08 | F37: =IF($E$37=0,0,E37/$E$37) -> 1

Sheet Calc_High
A1: High scenario: line items (Tk)
A2: Line item | B2: Year 1 | C2: Year 2 | D2: Year 3 | E2: Total | F2: Category | G2: One-time
A3: Core staff salaries and on-costs | B3: =(Assumptions!$B$16*12*Assumptions!$B$26+Assumptions!$B$17*12*Assumptions!$B$27+Assumptions!$B$18*12*Assumptions!$B$28+Assumptions!$B$19*12*Assumptions!$B$29+Assumptions!$B$20*12*Assumptions!$B$30+Assumptions!$B$21*12*Assumptions!$B$31+Assumptions!$B$22*12*Assumptions!$B$32+Assumptions!$B$23*12*Assumptions!$B$33+Assumptions!$B$24*12*Assumptions!$B$34+Assumptions!$B$25*12*Assumptions!$B$35)*Assumptions!$E$6*(1+Assumptions!$E$4)^0*Assumptions!$E$5 -> 16389000 | C3: =(Assumptions!$B$16*12*Assumptions!$C$26+Assumptions!$B$17*12*Assumptions!$C$27+Assumptions!$B$18*12*Assumptions!$C$28+Assumptions!$B$19*12*Assumptions!$C$29+Assumptions!$B$20*12*Assumptions!$C$30+Assumptions!$B$21*12*Assumptions!$C$31+Assumptions!$B$22*12*Assumptions!$C$32+Assumptions!$B$23*12*Assumptions!$C$33+Assumptions!$B$24*12*Assumptions!$C$34+Assumptions!$B$25*12*Assumptions!$C$35)*Assumptions!$E$6*(1+Assumptions!$E$4)^1 -> 38016000 | D3: =(Assumptions!$B$16*12*Assumptions!$D$26+Assumptions!$B$17*12*Assumptions!$D$27+Assumptions!$B$18*12*Assumptions!$D$28+Assumptions!$B$19*12*Assumptions!$D$29+Assumptions!$B$20*12*Assumptions!$D$30+Assumptions!$B$21*12*Assumptions!$D$31+Assumptions!$B$22*12*Assumptions!$D$32+Assumptions!$B$23*12*Assumptions!$D$33+Assumptions!$B$24*12*Assumptions!$D$34+Assumptions!$B$25*12*Assumptions!$D$35)*Assumptions!$E$6*(1+Assumptions!$E$4)^2 -> 51487920 | E3: =SUM(B3:D3) -> 105892920 | F3: Core staff | G3: no
A4: Part-time Bangla language editors | B4: =Assumptions!$B$36*(1+Assumptions!$E$4)^0 -> 1200000 | C4: =Assumptions!$C$36*(1+Assumptions!$E$4)^1 -> 1540000 | D4: =Assumptions!$D$36*(1+Assumptions!$E$4)^2 -> 1694000 | E4: =SUM(B4:D4) -> 4434000 | F4: Language editors and fellowships | G4: no
A5: Graduate fellowships | B5: =Assumptions!$B$37*Assumptions!$B$38*12*(1+Assumptions!$E$4)^0 -> 2880000 | C5: =Assumptions!$C$37*Assumptions!$B$38*12*(1+Assumptions!$E$4)^1 -> 5280000 | D5: =Assumptions!$D$37*Assumptions!$B$38*12*(1+Assumptions!$E$4)^2 -> 6969600 | E5: =SUM(B5:D5) -> 15129600 | F5: Language editors and fellowships | G5: no
A6: Servers, GPUs and storage | B6: =Assumptions!$B$39*Assumptions!$E$7*Assumptions!$E$3 -> 15525000 | C6: =Assumptions!$C$39*Assumptions!$E$7*Assumptions!$E$3 -> 13837500 | D6: =Assumptions!$D$39*Assumptions!$E$7*Assumptions!$E$3 -> 4050000 | E6: =SUM(B6:D6) -> 33412500 | F6: Compute and hosting | G6: yes
A7: Hosting, power, bandwidth and licences | B7: =Assumptions!$B$40*(1+Assumptions!$E$4)^0 -> 2500000 | C7: =Assumptions!$C$40*(1+Assumptions!$E$4)^1 -> 3520000 | D7: =Assumptions!$D$40*(1+Assumptions!$E$4)^2 -> 4598000 | E7: =SUM(B7:D7) -> 10618000 | F7: Compute and hosting | G7: no
A8: Stage 1 adaptation compute (if no national compute) | B8: =0 -> 0 | C8: =Assumptions!$E$10*Assumptions!$E$3 -> 2700000 | D8: =0 -> 0 | E8: =SUM(B8:D8) -> 2700000 | F8: Compute and hosting | G8: yes
A9: Staff computers (known omission) | B9: =Assumptions!$E$11*Assumptions!$B$60*Assumptions!$B$61*Assumptions!$E$3 -> 0 | C9: =Assumptions!$E$11*Assumptions!$C$60*Assumptions!$B$61*Assumptions!$E$3 -> 0 | D9: =Assumptions!$E$11*Assumptions!$D$60*Assumptions!$B$61*Assumptions!$E$3 -> 0 | E9: =SUM(B9:D9) -> 0 | F9: Compute and hosting | G9: yes
A10: Benchmark questions and gold passages | B10: =Assumptions!$B$41*Assumptions!$B$42*(1+Assumptions!$E$4)^0 -> 1250000 | C10: =Assumptions!$C$41*Assumptions!$B$42*(1+Assumptions!$E$4)^1 -> 2200000 | D10: =Assumptions!$D$41*Assumptions!$B$42*(1+Assumptions!$E$4)^2 -> 2117500 | E10: =SUM(B10:D10) -> 5567500 | F10: Data and annotation | G10: yes
A11: Out-of-scope questions for abstention tests | B11: =Assumptions!$B$43*Assumptions!$B$44*(1+Assumptions!$E$4)^0 -> 120000 | C11: =Assumptions!$C$43*Assumptions!$B$44*(1+Assumptions!$E$4)^1 -> 66000 | D11: =Assumptions!$D$43*Assumptions!$B$44*(1+Assumptions!$E$4)^2 -> 0 | E11: =SUM(B11:D11) -> 186000 | F11: Data and annotation | G11: yes
A12: Citation-support judgements | B12: =Assumptions!$B$45*Assumptions!$B$46*(1+Assumptions!$E$4)^0 -> 200000 | C12: =Assumptions!$C$45*Assumptions!$B$46*(1+Assumptions!$E$4)^1 -> 440000 | D12: =Assumptions!$D$45*Assumptions!$B$46*(1+Assumptions!$E$4)^2 -> 484000 | E12: =SUM(B12:D12) -> 1124000 | F12: Data and annotation | G12: no
A13: OCR correction | B13: =Assumptions!$B$47*(1+Assumptions!$E$4)^0 -> 2000000 | C13: =Assumptions!$C$47*(1+Assumptions!$E$4)^1 -> 2200000 | D13: =Assumptions!$D$47*(1+Assumptions!$E$4)^2 -> 1815000 | E13: =SUM(B13:D13) -> 6015000 | F13: Data and annotation | G13: no
A14: Data agreements and custodian liaison | B14: =Assumptions!$B$48*(1+Assumptions!$E$4)^0 -> 500000 | C14: =Assumptions!$C$48*(1+Assumptions!$E$4)^1 -> 440000 | D14: =Assumptions!$D$48*(1+Assumptions!$E$4)^2 -> 363000 | E14: =SUM(B14:D14) -> 1303000 | F14: Data and annotation | G14: no
A15: Training of officials | B15: =Assumptions!$B$49*Assumptions!$B$50*(1+Assumptions!$E$4)^0 -> 1500000 | C15: =Assumptions!$C$49*Assumptions!$B$50*(1+Assumptions!$E$4)^1 -> 3300000 | D15: =Assumptions!$D$49*Assumptions!$B$50*(1+Assumptions!$E$4)^2 -> 3630000 | E15: =SUM(B15:D15) -> 8430000 | F15: Training and outreach | G15: no
A16: Specialist courses and bilingual materials | B16: =Assumptions!$B$51*(1+Assumptions!$E$4)^0 -> 800000 | C16: =Assumptions!$C$51*(1+Assumptions!$E$4)^1 -> 1210000 | D16: =Assumptions!$D$51*(1+Assumptions!$E$4)^2 -> 1331000 | E16: =SUM(B16:D16) -> 3341000 | F16: Training and outreach | G16: no
A17: Engagement events, P5 survey data, travel and open-access fees (known omission) | B17: =Assumptions!$E$11*Assumptions!$B$59*(1+Assumptions!$E$4)^0 -> 0 | C17: =Assumptions!$E$11*Assumptions!$B$59*(1+Assumptions!$E$4)^1 -> 0 | D17: =Assumptions!$E$11*Assumptions!$B$59*(1+Assumptions!$E$4)^2 -> 0 | E17: =SUM(B17:D17) -> 0 | F17: Training and outreach | G17: no
A18: Annual independent audit of systems | B18: =Assumptions!$B$52*(1+Assumptions!$E$4)^0 -> 300000 | C18: =Assumptions!$C$52*(1+Assumptions!$E$4)^1 -> 330000 | D18: =Assumptions!$D$52*(1+Assumptions!$E$4)^2 -> 363000 | E18: =SUM(B18:D18) -> 993000 | F18: Governance, audit and evaluation | G18: no
A19: Baseline study | B19: =Assumptions!$B$53*(1+Assumptions!$E$4)^0 -> 600000 | C19: =Assumptions!$C$53*(1+Assumptions!$E$4)^1 -> 0 | D19: =Assumptions!$D$53*(1+Assumptions!$E$4)^2 -> 0 | E19: =SUM(B19:D19) -> 600000 | F19: Governance, audit and evaluation | G19: yes
A20: ERRC and board honoraria | B20: =Assumptions!$B$54*(1+Assumptions!$E$4)^0 -> 800000 | C20: =Assumptions!$C$54*(1+Assumptions!$E$4)^1 -> 880000 | D20: =Assumptions!$D$54*(1+Assumptions!$E$4)^2 -> 968000 | E20: =SUM(B20:D20) -> 2648000 | F20: Governance, audit and evaluation | G20: no
A21: Independent final evaluation | B21: =Assumptions!$B$55*(1+Assumptions!$E$4)^0 -> 0 | C21: =Assumptions!$C$55*(1+Assumptions!$E$4)^1 -> 0 | D21: =Assumptions!$D$55*(1+Assumptions!$E$4)^2 -> 3025000 | E21: =SUM(B21:D21) -> 3025000 | F21: Governance, audit and evaluation | G21: yes
A22: Independent mid-term evaluation | B22: =Assumptions!$B$56*(1+Assumptions!$E$4)^0 -> 0 | C22: =Assumptions!$C$56*(1+Assumptions!$E$4)^1 -> 2200000 | D22: =Assumptions!$D$56*(1+Assumptions!$E$4)^2 -> 0 | E22: =SUM(B22:D22) -> 2200000 | F22: Governance, audit and evaluation | G22: yes
A23: Legal review | B23: =Assumptions!$B$57*(1+Assumptions!$E$4)^0 -> 800000 | C23: =Assumptions!$C$57*(1+Assumptions!$E$4)^1 -> 0 | D23: =Assumptions!$D$57*(1+Assumptions!$E$4)^2 -> 0 | E23: =SUM(B23:D23) -> 800000 | F23: Governance, audit and evaluation | G23: yes
A24: Penetration test and red team | B24: =Assumptions!$B$58*(1+Assumptions!$E$4)^0 -> 600000 | C24: =Assumptions!$C$58*(1+Assumptions!$E$4)^1 -> 660000 | D24: =Assumptions!$D$58*(1+Assumptions!$E$4)^2 -> 726000 | E24: =SUM(B24:D24) -> 1986000 | F24: Governance, audit and evaluation | G24: no
A26: Summary by category
A27: Row | B27: Year 1 | C27: Year 2 | D27: Year 3 | E27: Total | F27: Share of total
A28: Core staff | B28: =SUM(B3) -> 16389000 | C28: =SUM(C3) -> 38016000 | D28: =SUM(D3) -> 51487920 | E28: =SUM(E3) -> 105892920 | F28: =IF($E$37=0,0,E28/$E$37) -> 0.41940012
A29: Language editors and fellowships | B29: =SUM(B4,B5) -> 4080000 | C29: =SUM(C4,C5) -> 6820000 | D29: =SUM(D4,D5) -> 8663600 | E29: =SUM(E4,E5) -> 19563600 | F29: =IF($E$37=0,0,E29/$E$37) -> 0.077483709
A30: Compute and hosting | B30: =SUM(B6,B7,B8,B9) -> 18025000 | C30: =SUM(C6,C7,C8,C9) -> 20057500 | D30: =SUM(D6,D7,D8,D9) -> 8648000 | E30: =SUM(E6,E7,E8,E9) -> 46730500 | F30: =IF($E$37=0,0,E30/$E$37) -> 0.18508109
A31: Data and annotation | B31: =SUM(B10,B11,B12,B13,B14) -> 4070000 | C31: =SUM(C10,C11,C12,C13,C14) -> 5346000 | D31: =SUM(D10,D11,D12,D13,D14) -> 4779500 | E31: =SUM(E10,E11,E12,E13,E14) -> 14195500 | F31: =IF($E$37=0,0,E31/$E$37) -> 0.05622278
A32: Training and outreach | B32: =SUM(B15,B16,B17) -> 2300000 | C32: =SUM(C15,C16,C17) -> 4510000 | D32: =SUM(D15,D16,D17) -> 4961000 | E32: =SUM(E15,E16,E17) -> 11771000 | F32: =IF($E$37=0,0,E32/$E$37) -> 0.046620291
A33: Governance, audit and evaluation | B33: =SUM(B18,B19,B20,B21,B22,B23,B24) -> 3100000 | C33: =SUM(C18,C19,C20,C21,C22,C23,C24) -> 4070000 | D33: =SUM(D18,D19,D20,D21,D22,D23,D24) -> 5082000 | E33: =SUM(E18,E19,E20,E21,E22,E23,E24) -> 12252000 | F33: =IF($E$37=0,0,E33/$E$37) -> 0.048525343
A34: Direct costs | B34: =SUM(B28:B33) -> 47964000 | C34: =SUM(C28:C33) -> 78819500 | D34: =SUM(D28:D33) -> 83622020 | E34: =SUM(E28:E33) -> 210405520 | F34: =IF($E$37=0,0,E34/$E$37) -> 0.83333333
A35: Host overheads | B35: =B34*Assumptions!$E$8 -> 4796400 | C35: =C34*Assumptions!$E$8 -> 7881950 | D35: =D34*Assumptions!$E$8 -> 8362202 | E35: =SUM(B35:D35) -> 21040552 | F35: =IF($E$37=0,0,E35/$E$37) -> 0.083333333
A36: Contingency | B36: =B34*Assumptions!$E$9 -> 4796400 | C36: =C34*Assumptions!$E$9 -> 7881950 | D36: =D34*Assumptions!$E$9 -> 8362202 | E36: =SUM(B36:D36) -> 21040552 | F36: =IF($E$37=0,0,E36/$E$37) -> 0.083333333
A37: Total | B37: =B34+B35+B36 -> 57556800 | C37: =C34+C35+C36 -> 94583400 | D37: =D34+D35+D36 -> 100346424 | E37: =E34+E35+E36 -> 252486624 | F37: =IF($E$37=0,0,E37/$E$37) -> 1
